<?xml version="1.0" encoding="UTF-8"?>
<!-- Generated by org.testng.reporters.JUnitReportReporter -->
<testsuite hostname="PUN-5G4T5H2" name="CollectionPractice.ExceptionHandling" tests="1" failures="0" timestamp="7 May 2020 14:11:11 GMT" time="0.016" errors="1">
  <testcase name="test" time="0.016" classname="CollectionPractice.ExceptionHandling">
    <error type="java.lang.Error" message="Unresolved compilation problems: 
	Syntax error on token &quot;catch&quot;, ( expected
	Syntax error, insert &quot;-&gt; LambdaBody&quot; to complete LambdaExpression
	Syntax error, insert &quot;AssignmentOperator Expression&quot; to complete Assignment
	Syntax error, insert &quot;;&quot; to complete Statement
">
      <![CDATA[java.lang.Error: Unresolved compilation problems: 
	Syntax error on token "catch", ( expected
	Syntax error, insert "-> LambdaBody" to complete LambdaExpression
	Syntax error, insert "AssignmentOperator Expression" to complete Assignment
	Syntax error, insert ";" to complete Statement

	at CollectionPractice.ExceptionHandling.test(ExceptionHandling.java:22)
	at sun.reflect.NativeMethodAccessorImpl.invoke0(Native Method)
	at sun.reflect.NativeMethodAccessorImpl.invoke(Unknown Source)
	at sun.reflect.DelegatingMethodAccessorImpl.invoke(Unknown Source)
	at java.lang.reflect.Method.invoke(Unknown Source)
	at org.testng.internal.MethodInvocationHelper.invokeMethod(MethodInvocationHelper.java:86)
	at org.testng.internal.Invoker.invokeMethod(Invoker.java:646)
	at org.testng.internal.Invoker.invokeTestMethod(Invoker.java:823)
	at org.testng.internal.Invoker.invokeTestMethods(Invoker.java:1131)
	at org.testng.internal.TestMethodWorker.invokeTestMethods(TestMethodWorker.java:129)
	at org.testng.internal.TestMethodWorker.run(TestMethodWorker.java:112)
	at org.testng.TestRunner.privateRun(TestRunner.java:778)
	at org.testng.TestRunner.run(TestRunner.java:632)
	at org.testng.SuiteRunner.runTest(SuiteRunner.java:366)
	at org.testng.SuiteRunner.runSequentially(SuiteRunner.java:361)
	at org.testng.SuiteRunner.privateRun(SuiteRunner.java:319)
	at org.testng.SuiteRunner.run(SuiteRunner.java:268)
	at org.testng.SuiteRunnerWorker.runSuite(SuiteRunnerWorker.java:52)
	at org.testng.SuiteRunnerWorker.run(SuiteRunnerWorker.java:86)
	at org.testng.TestNG.runSuitesSequentially(TestNG.java:1225)
	at org.testng.TestNG.runSuitesLocally(TestNG.java:1150)
	at org.testng.TestNG.runSuites(TestNG.java:1075)
	at org.testng.TestNG.run(TestNG.java:1047)
	at org.testng.remote.AbstractRemoteTestNG.run(AbstractRemoteTestNG.java:126)
	at org.testng.remote.RemoteTestNG.initAndRun(RemoteTestNG.java:137)
	at org.testng.remote.RemoteTestNG.main(RemoteTestNG.java:58)
]]>
    </error>
  </testcase> <!-- test -->
</testsuite> <!-- CollectionPractice.ExceptionHandling -->
